<?xml version="1.0" encoding="utf-8"?>
<mujoco>
   <include file="shared_config.xml"></include>
    <worldbody>
        <include file="sawyer_xyz_base.xml"></include>
        <body name="obj0" pos="0.025 0.025 0.025">
            <joint name="objGeom0_x" type="free" limited="false" damping="0.01"></joint>
            <geom size="0.025 0.025 0.025" type="box" condim="3" name="objGeom0" mass="5" friction="0.1 0.1 0.2"></geom>
            <site name="obj0" pos="0 0 0" size="0.02 0.02 0.02" rgba="0.0 1.0 0.0 1" type="sphere"></site>
        </body>

        <body name="obj1" pos="0.025 0.025 0.025">
            <joint name="objGeom1_x" type="free" limited="false" damping="0.01"></joint>
            <geom size="0.025 0.025 0.025" type="box" condim="3" name="objGeom1" mass="5" friction="0.1 0.1 0.2"></geom>
            <site name="obj1" pos="0 0 0" size="0.02 0.02 0.02" rgba="1 .5 1 1" type="sphere"></site>
        </body>
      
        <body name="obj2" pos="0.025 0.025 0.025">
            <joint name="objGeom2_x" type="free" limited="false" damping="0.01"></joint>
            <geom size="0.025 0.025 0.025" type="box" condim="3" name="objGeom2" mass="5" friction="0.1 0.1 0.2"></geom>
            <site name="obj2" pos="0 0 0" size="0.02 0.02 0.02" rgba="0 0.0 1 1" type="sphere"></site>
        </body>

        <camera mode="fixed" name="cam0" pos="-0.0 1.42 0.85" quat="0.924 -0.383 0 0"/>
      

        <body name="door" pos="0.1 0.85 0.1">
                <joint name="doorjoint" pos="-.16 0 0" axis="0 0 1"
                       type="hinge" limited="true" range="-1.5708 1.5708" damping="1" armature="0" />
                <geom type="box" pos="0 0 0" size="0.12 0.01 0.1"
                      rgba=".1 .1 .9 1" contype="1" conaffinity="1" material="light_wood"/>
                <!--front, parallel to door-->
                <geom type="box" pos="0.1 -0.15 0.05" size="0.04 0.01 0.02" rgba="0 0 0 1" contype="1" conaffinity="1" name="handle" material="light_wood"/>
                <!--front-->
                <geom type="box" pos="0.14 -0.075 0.05" size="0.01 0.075 0.02" rgba="0 0 0 1" contype="1" conaffinity="1" material="light_wood"/>
        </body>

    </worldbody>

    <!-- <actuator>
        <motor joint="right_j0" ctrlrange="-100.0 100.0" ctrllimited="false"/>
        <motor joint="right_j1" ctrlrange="-100.0 100.0" ctrllimited="false"/>
        <motor joint="right_j2" ctrlrange="-100.0 100.0" ctrllimited="false"/>
        <motor joint="right_j3" ctrlrange="-100.0 100.0" ctrllimited="false"/>
        <motor joint="right_j4" ctrlrange="-100.0 100.0" ctrllimited="false"/>
        <motor joint="right_j5" ctrlrange="-100.0 100.0" ctrllimited="false"/>
        <motor joint="right_j6" ctrlrange="-100.0 100.0" ctrllimited="false"/>
        <motor gear="100" joint="r_close" name="slide"/>
    </actuator> -->
    <actuator>
        <position ctrllimited="true" ctrlrange="-1 1" joint="r_close" kp="400"  user="1"/>
        <position ctrllimited="true" ctrlrange="-1 1" joint="l_close" kp="400"  user="1"/>
    </actuator>

</mujoco>
