<mujoco>
    <include file="basic_scene.xml"/>
    <include file="drawer_dependencies.xml"/>
    <include file="block_dependencies.xml"/>
    <include file="xyz_base_dependencies.xml"/>
    <!--<size nconmax="200"/>-->
    <size njmax="1000" nconmax="1000"/>
    <worldbody>
        <include file="sawyer_xyz_base_no_table.xml"></include>

        <camera mode="fixed" name="cam0" pos="0.78 0.12 0.75" quat="0.3858 -0.23 0.4379 -0.7886"/>

        <body name="drawer" pos="0.2 0.8 0">
            <include file="drawer.xml"/>
        </body>

        <body name="drawer2" pos="-0.2 0.8 0">
            <body childclass="drawer_base">
                <body name="drawercase_link2" pos="0 0 0.084">
                    <geom material="drawer_beige" mesh="drawercase"/>
                    <geom class="drawer_col" pos="-0.11 0 0" size="0.008 0.1 0.084" type="box" mass=".05"/>
                    <geom class="drawer_col" pos="0.11 0 0" size="0.008 0.1 0.084" type="box" mass=".05"/>
                    <geom class="drawer_col" pos="0 0.092 -0.008" size="0.102 0.008 0.076" type="box" mass=".05"/>
                    <geom class="drawer_col" pos="0 -0.008 -0.07" size="0.102 0.092 0.014" type="box" mass=".05"/>
                    <geom class="drawer_col" pos="0 0 0.076" size="0.102 0.1 0.008" type="box" mass=".05"/>
                    <body name="drawer_link2" pos="0 -0.01 0.006">
                        <joint type="slide" range="-0.16 -0.05" axis="0 1 0" name="goal_slidey2" pos="0 0 0" damping="5"/>
                        <geom material="drawer_beige" mesh="drawer"/>
                        <geom material="drawer_white" mesh="drawerhandle" pos="0 -0.114 0" name="handle2"/>
                        <site name="handleStart2" pos="0 -0.114 0.016" size="0.01" rgba="1 0 0 1"/>
                        <geom class="drawer_col" pos="0 -0.082 0.008" size="0.1 0.008 0.052" type="box" mass=".04" name="drawer_wall22"/>
                        <geom class="drawer_col" pos="0 0.082 0.008" size="0.1 0.008 0.052" type="box" mass=".04"/>
                        <geom class="drawer_col" pos="-0.092 0 0.008" size="0.008 0.074 0.052" type="box" mass=".04"/>
                        <geom class="drawer_col" pos="0.092 0 0.008" size="0.008 0.074 0.052" type="box" mass=".04"/>
                        <geom class="drawer_col" pos="0 0 -0.052" size="0.1 0.09 0.008" type="box" mass=".04"/>
                        <geom class="drawer_col" euler="1.571 0 0" pos="-0.05 -0.12 0.0" size="0.009 0.03" type="capsule" mass=".06"/>
                        <geom class="drawer_col" euler="0 1.57 0" pos="0 -0.15 0" size="0.009 0.05" type="capsule" mass=".06"/>
                        <geom class="drawer_col" euler="1.57 0 0" pos="0.05 -0.12 0" size="0.009 0.03" type="capsule" mass=".06"/>
                    </body>
                </body>
            </body>
        </body>

        <site name="goal" pos="0. 0.74 0.05" size="0.02"
              rgba="0 0.8 0 1"/>

    </worldbody>

    <!-- <actuator>
        <motor joint="right_j0" ctrlrange="-100.0 100.0" ctrllimited="false"/>
        <motor joint="right_j1" ctrlrange="-100.0 100.0" ctrllimited="false"/>
        <motor joint="right_j2" ctrlrange="-100.0 100.0" ctrllimited="false"/>
        <motor joint="right_j3" ctrlrange="-100.0 100.0" ctrllimited="false"/>
        <motor joint="right_j4" ctrlrange="-100.0 100.0" ctrllimited="false"/>
        <motor joint="right_j5" ctrlrange="-100.0 100.0" ctrllimited="false"/>
        <motor joint="right_j6" ctrlrange="-100.0 100.0" ctrllimited="false"/>
        <motor gear="100" joint="r_close" name="slide"/>
    </actuator> -->
    <actuator>
        <position ctrllimited="true" ctrlrange="-1 1" joint="r_close" kp="400"  user="1"/>
        <position ctrllimited="true" ctrlrange="-1 1" joint="l_close" kp="400"  user="1"/>
    </actuator>
    <equality>
        <weld body1="mocap" body2="hand" solref="0.02 1"></weld>
    </equality>

</mujoco>
